def throws an error {
  GeneralError "An error :)"
}

try {
  throws an error
} catch (err) {
  General => {
    print "An error occurred. The message was:"
    print (err.msg)
  }
}

print "After the try-catch"